{"uuid": "71da3927-e94b-4df3-be62-9156e80a615b", "children": ["b4e22b81-fcb6-4aad-88e4-49f95c8ea285"], "befores": [{"name": "_Class__pytest_setup_class", "status": "broken", "statusDetails": {"message": "selenium.common.exceptions.WebDriverException: Message: An unknown server-side error occurred while processing the command. Original error: Cannot start the 'com.itcast.toutiaoApp' application. Visit https://github.com/appium/appium/blob/master/docs/en/writing-running-appium/android/activity-startup.md for troubleshooting. Original error: Error executing adbExec. Original error: 'Command ''D:\\\\Program Files (x86)\\\\Android\\\\android-sdk\\\\platform-tools\\\\adb.exe' -P 5037 -s 127.0.0.1\\:62001 shell am start -W -n com.itcast.toutiaoApp/.MainActivity -S' timed out after 20000ms'. Try to increase the 20000ms adb execution timeout represented by 'adbExecTimeout' capability\n\n", "trace": "  File \"c:\\program files (x86)\\python\\lib\\site-packages\\pluggy\\callers.py\", line 187, in _multicall\n    res = hook_impl.function(*args)\n  File \"c:\\program files (x86)\\python\\lib\\site-packages\\_pytest\\fixtures.py\", line 964, in pytest_fixture_setup\n    result = call_fixture_func(fixturefunc, request, kwargs)\n  File \"c:\\program files (x86)\\python\\lib\\site-packages\\_pytest\\fixtures.py\", line 788, in call_fixture_func\n    res = next(it)\n  File \"c:\\program files (x86)\\python\\lib\\site-packages\\_pytest\\python.py\", line 701, in xunit_setup_class_fixture\n    _call_with_optional_argument(func, self.obj)\n  File \"c:\\program files (x86)\\python\\lib\\site-packages\\_pytest\\python.py\", line 632, in _call_with_optional_argument\n    func(arg)\n  File \"F:\\Pycharm\\uiAutoTestHmtt\\scripts\\test05_app_login.py\", line 13, in setup_class\n    driver = GetDriver.get_app_driver()\n  File \"F:\\Pycharm\\uiAutoTestHmtt\\tools\\get_driver.py\", line 59, in get_app_driver\n    cls.__app_driver = appium.webdriver.Remote(\"http://127.0.0.1:4723/wd/hub\", desired_caps)\n  File \"c:\\program files (x86)\\python\\lib\\site-packages\\appium_python_client-0.25-py3.6.egg\\appium\\webdriver\\webdriver.py\", line 36, in __init__\n    super(WebDriver, self).__init__(command_executor, desired_capabilities, browser_profile, proxy, keep_alive)\n  File \"c:\\program files (x86)\\python\\lib\\site-packages\\selenium\\webdriver\\remote\\webdriver.py\", line 157, in __init__\n    self.start_session(capabilities, browser_profile)\n  File \"c:\\program files (x86)\\python\\lib\\site-packages\\selenium\\webdriver\\remote\\webdriver.py\", line 252, in start_session\n    response = self.execute(Command.NEW_SESSION, parameters)\n  File \"c:\\program files (x86)\\python\\lib\\site-packages\\selenium\\webdriver\\remote\\webdriver.py\", line 321, in execute\n    self.error_handler.check_response(response)\n  File \"c:\\program files (x86)\\python\\lib\\site-packages\\selenium\\webdriver\\remote\\errorhandler.py\", line 242, in check_response\n    raise exception_class(message, screen, stacktrace)\n"}, "start": 1594384995014, "stop": 1594385085034}], "start": 1594384995014, "stop": 1594385086132}